Workbook

Sheet PER FITUR
A1: RENCANA ANGGARAN BIAYA (RAB)
A2: Website Manajemen Kos (SIMA KOS)
A4: No | B4: Uraian | C4: Volume | F4: Harga
C5: Jumlah | D5: Durasi | E5: Total | F5: Satuan | G5: Total
A6: A. Pengembangan Fitur (Volume dalam Orang-Hari)
A7: 1 | B7: Desain UI/UX Aplikasi (seluruh halaman) | C7: 1 | D7: 6 | E7: =C7*D7 -> 6 | F7: 30000 | G7: =E7*F7 -> 180000
A8: 2 | B8: Autentikasi & Verifikasi User (Register, Login, Verifikasi Admin) | C8: 2 | D8: 5 | E8: =C8*D8 -> 10 | F8: 50000 | G8: =E8*F8 -> 500000
A9: 3 | B9: Melihat & Memilih Kamar (listing & detail kamar) | C9: 2 | D9: 4 | E9: =C9*D9 -> 8 | F9: 50000 | G9: =E9*F9 -> 400000
A10: 4 | B10: Integrasi Chat WhatsApp Langsung dari Web | C10: 1 | D10: 3 | E10: =C10*D10 -> 3 | F10: 50000 | G10: =E10*F10 -> 150000
A11: 5 | B11: Booking Kamar (termasuk validasi ketersediaan) | C11: 2 | D11: 7 | E11: =C11*D11 -> 14 | F11: 50000 | G11: =E11*F11 -> 700000
A12: 6 | B12: Pembatalan Booking | C12: 2 | D12: 3 | E12: =C12*D12 -> 6 | F12: 50000 | G12: =E12*F12 -> 300000
A13: 7 | B13: Pengajuan Perpanjangan Booking | C13: 2 | D13: 4 | E13: =C13*D13 -> 8 | F13: 50000 | G13: =E13*F13 -> 400000
A14: 8 | B14: Riwayat Booking & Riwayat Pembayaran (Profil User) | C14: 2 | D14: 3 | E14: =C14*D14 -> 6 | F14: 50000 | G14: =E14*F14 -> 300000
A15: 9 | B15: Verifikasi Pembayaran (Admin) | C15: 2 | D15: 4 | E15: =C15*D15 -> 8 | F15: 50000 | G15: =E15*F15 -> 400000
A16: 10 | B16: Kelola Data Kos & Kamar (Admin) | C16: 2 | D16: 5 | E16: =C16*D16 -> 10 | F16: 50000 | G16: =E16*F16 -> 500000
A17: 11 | B17: Kelola Pengajuan User - Pembatalan/Perpanjangan (Admin) | C17: 2 | D17: 4 | E17: =C17*D17 -> 8 | F17: 50000 | G17: =E17*F17 -> 400000
A18: 12 | B18: Dashboard & Laporan Histori Transaksi (Admin) | C18: 1 | D18: 5 | E18: =C18*D18 -> 5 | F18: 40000 | G18: =E18*F18 -> 200000
A19: 13 | B19: Testing & QA Keseluruhan Sistem | C19: 1 | D19: 5 | E19: =C19*D19 -> 5 | F19: 20000 | G19: =E19*F19 -> 100000
A20: Subtotal A. Pengembangan Fitur | G20: =SUM(G7:G19) -> 4530000
A21: B. Infrastruktur & Lisensi (Volume dalam Paket/Tahun)
A22: 14 | B22: Hosting & Domain (1 tahun) | C22: 1 | D22: 1 | E22: =C22*D22 -> 1 | F22: 4312000 | G22: =E22*F22 -> 4312000
A23: 15 | B23: Supabase Pro Plan (1 tahun, estimasi) | C23: 1 | D23: 1 | E23: =C23*D23 -> 1 | F23: 5390000 | G23: =E23*F23 -> 5390000
A24: 16 | B24: WhatsApp API pihak ketiga, Fonnte (1 tahun, estimasi) | C24: 1 | D24: 1 | E24: =C24*D24 -> 1 | F24: 4260000 | G24: =E24*F24 -> 4260000
A25: Subtotal B. Infrastruktur & Lisensi | G25: =SUM(G22:G24) -> 13962000
A26: C. Biaya Operasional Lain
A27: 17 | B27: Pemasaran & Promosi (konten medsos) | C27: 1 | D27: 1 | E27: =C27*D27 -> 1 | F27: 500000 | G27: =E27*F27 -> 500000
A28: 18 | B28: Dokumentasi & Pelatihan Penggunaan untuk Klien | C28: 1 | D28: 1 | E28: =C28*D28 -> 1 | F28: 100000 | G28: =E28*F28 -> 100000
A29: Subtotal C. Biaya Operasional Lain | G29: =SUM(G27:G28) -> 600000
A31: Jumlah Subtotal (A+B+C) | G31: =G20+G25+G29 -> 19092000
A32: Biaya Tak Terduga (10%) | G32: =G31*10% -> 1909200
A33: TOTAL ANGGARAN | G33: =G31+G32 -> 21001200

Sheet Pertanyaan
B1: Narasumber: HRD Suara Surabaya
B2: Konteks: Aplikasi sudah dibuat dan sudah dicoba oleh narasumber. Wawancara bertujuan mengevaluasi kesesuaian, kekurangan, dan kesiapan aplikasi.
B4: Kriteria | C4: Pertanyaan | D4: Target Jawaban | G4: tambahin indikator, referensi, target
B5: Kesesuaian alur proses bisnis | C5: Apakah alur penggunaannya sudah sesuai dengan proses pengelolaan kos yang dilakukan saat ini? | D5: Sudah sesuai. Alurnya mirip dengan yang saya lakukan selama ini, calon penghuni mengajukan booking, saya cek, lalu kamar dikonfirmasi dan penghuni mulai menempati. | G5: RAB DAN NOMINAL
C6: Apakah alur booking (calon penghuni memesan, pemilik mengonfirmasi, status kamar berubah) sudah sama dengan cara Bapak/Ibu menerima penghuni selama ini? | D6: Sudah sama. Calon penghuni memilih kamar dan mengisi formulir, saya mengonfirmasi, lalu status kamar otomatis berubah dari kosong menjadi dipesan. | G6: apakah bapak pernah menggunakan aplikasi serupa sebelumnya?
B7: Fungsi booking dan manajemen kamar | C7: Apakah data yang diminta dari calon penghuni pada formulir booking sudah lengkap dan sesuai dengan data yang selama ini Bapak/Ibu butuhkan? | D7: Sudah cukup lengkap. Nama, nomor HP, dan foto KTP sudah ada.
C8: Apakah status kamar (kosong, dipesan, terisi) yang ditampilkan di aplikasi sudah akurat dan membantu Bapak/Ibu mengetahui ketersediaan kamar? | D8: Sudah akurat dan sangat membantu. | G8: dalam pengembangan yang dibayar itu fungsi
C9: Apakah aplikasi sudah dapat mencegah atau menangani masalah booking ganda pada kamar yang sama dengan baik? | D9: Sudah aman. Saat kamar sudah dipesan satu orang, calon penghuni lain tidak bisa memilih kamar itu, jadi tidak ada lagi kejadian dua orang memesan kamar yang sama. | G9: seharusnya satu pertanyaan satu jawaban
C10: Apakah pengaturan DP/uang jaminan, batas waktu penahanan kamar, dan pembatalan booking di aplikasi sudah sesuai dengan aturan di kos Bapak/Ibu? | D10: Sudah sesuai. DP dan batas penahanan kamar sudah cocok, yaitu 3 hari. Kalau tidak jadi masuk, DP tidak dikembalikan, dan itu perlu dimasukkan. | G10: misal, apakah ibu menggunakan mamikos?
B11: Fungsi pembayaran dan tagihan | C11: Apakah proses pencatatan pembayaran di aplikasi sudah sesuai dengan kebiasaan Bapak/Ibu (metode bayar, tanggal jatuh tempo, bukti pembayaran)? | D11: Sudah sesuai. Pembayaran dicatat per bulan dengan tanggal jatuh tempo, metode transfer atau tunai, dan bukti bayarnya bisa diunggah. Lebih rapi daripada buku catatan saya. | G11: bagaimana selama ini penghuni kos mendapatkan informasi keberadaan kos ibu, hingga akhirnya booking kos ibu?
C12: Apakah fitur bukti pembayaran dan riwayat transaksi di aplikasi sudah cukup membantu Bapak/Ibu dalam mencatat dan menelusuri pembayaran setiap penghuni? | D12: Sudah membantu. Setiap pembayaran tercatat lengkap dengan tanggal, nominal, dan bukti transfernya, jadi kalau ada penghuni yang bertanya soal pembayarannya, saya bisa langsung cek riwayatnya tanpa membuka buku catatan.
C13: Apakah informasi tunggakan atau tagihan yang jatuh tempo di aplikasi sudah jelas dan memudahkan Bapak/Ibu dalam menagih penghuni? | D13: Cukup jelas. Penghuni yang menunggak langsung kelihatan di daftar tagihan. Fitur pengingat otomatis lewat WhatsApp juga sudah cukup bagus sehingga tidak perlu menagih satu per satu. | G13: CARI DEVELOPER BESERTA GAJIANYA
B14: Kualitas data, informasi, dan laporan | C14: Apakah data penghuni dan riwayat sewa yang tersimpan di aplikasi sudah cukup untuk kebutuhan pengelolaan kos? | D14: Sudah cukup. Data penghuni, tanggal masuk, dan riwayat pembayaran sudah tersimpan. | G14: TARGETNYA APA
C15: Apakah informasi yang ditampilkan di aplikasi (dashboard, daftar kamar, daftar penghuni) sudah sesuai dengan kebutuhan Bapak/Ibu? | D15: Sudah sesuai. Dashboard menampilkan jumlah kamar terisi, kosong, dan pemasukan bulan ini, yaitu hal yang paling sering saya cek. Daftar kamar dan penghuni juga mudah dibaca.
C16: Apakah laporan yang dihasilkan (pemasukan, tingkat hunian, tunggakan) sudah cukup membantu Bapak/Ibu dalam memantau kondisi dan mengambil keputusan? | D16: Cukup membantu. Laporan pemasukan bulanan dan tingkat hunian sudah cukup untuk melihat kondisi kos.
C17: Apakah ada data atau laporan lain yang menurut Bapak/Ibu masih perlu ditampilkan? | D17: Ada. Saya butuh rekap daftar penghuni yang akan habis masa sewanya, supaya bisa mencari penghuni baru lebih awal.
B18: Kelengkapan fitur | C18: Apakah ada proses pengelolaan kos yang masih dilakukan secara manual dan belum terakomodasi dalam aplikasi (misalnya perpanjangan sewa, pindah kamar, check-out, pengembalian deposit)? | D18: Masih ada. Perpanjangan sewa, pindah kamar, dan pengembalian uang jaminan saat check-out masih saya catat manual di buku.
C19: Apakah ada fitur yang menurut Bapak/Ibu masih kurang atau perlu ditambahkan? | D19: Fitur pengaduan atau perbaikan fasilitas dari penghuni.
C20: Apakah ada fitur yang sebenarnya tidak diperlukan atau jarang digunakan? | D20: Tidak ada.
B21: Kemudahan penggunaan dan performa | C21: Apakah terdapat bagian aplikasi yang sulit dipahami atau digunakan (menu, istilah, tombol, tampilan)? | D21: Secara umum mudah dipahami.
C22: Bagaimana penilaian Bapak/Ibu terhadap kecepatan dan kemudahan aplikasi saat digunakan, baik dari komputer maupun HP? | D22: Cepat dan nyaman, terutama dari HP, karena saya lebih sering membuka lewat HP. Kadang loading halaman laporan agak lama, tapi masih bisa diterima.
B23: Keamanan dan hak akses | C23: Apakah pembagian hak akses pengguna (pemilik, admin, penghuni) sudah sesuai dengan peran masing-masing di kos? | D23: Sudah sesuai. Saya sebagai pemilik bisa melihat semua data termasuk keuangan, penghuni hanya melihat data serta tagihannya sendiri.
C24: Apakah Bapak/Ibu merasa data penghuni dan data keuangan di aplikasi sudah cukup aman dan terjaga kerahasiaannya? | D24: Cukup aman karena harus login dan tiap peran punya batas akses. Tapi saya ingin data dicadangkan secara berkala supaya tidak hilang kalau ada masalah.
B25: Manfaat dan kesiapan implementasi | C25: Apa manfaat terbesar yang Bapak/Ibu rasakan dari aplikasi ini, dan apakah ada kekurangannya? | D25: Manfaat terbesar: hemat waktu, data lebih rapi, dan tidak ada tagihan yang terlewat. Dulu mencari data penghuni lama bisa memakan waktu lama, sekarang cukup beberapa detik. Kekurangannya hanya perlu waktu belajar di awal.
C26: Apa yang menurut Bapak/Ibu perlu diperbaiki terlebih dahulu? | D26: Sudah cukup baik, yang perlu diperbaiki lebih dulu hanya tampilan di HP agar lebih rapi. Selain itu saya rasa aplikasi sudah siap dipakai sehari-hari.
C27: Apakah Bapak/Ibu atau pengelola lain membutuhkan pelatihan atau panduan penggunaan agar dapat memakai aplikasi ini dengan lancar? | D27: Perlu, tapi tidak lama. Admin kos perlu dilatih sekali dan sebaiknya diberi buku panduan singkat atau video, supaya bisa dipelajari ulang kalau lupa.
C28: Apakah ada kebutuhan atau perubahan lain yang Bapak/Ibu harapkan sebelum aplikasi digunakan secara penuh? | D28: Data penghuni yang sekarang perlu dimasukkan dulu ke aplikasi, dan saya ingin ada masa percobaan satu atau dua bulan sebelum benar-benar menggantikan buku catatan.
C29: Apakah aplikasi ini sudah sesuai dengan kebutuhan pengelolaan kos dan bersedia digunakan setelah tahap pengembangan selesai? | D29: Aplikasi ini sudah cukup sesuai dengan kebutuhan pengelolaan kos saya, dan saya bersedia menggunakannya setelah perbaikan selesai, terutama penambahan fitur pengingat tagihan dan check-out.

Sheet RAB - Biaya Produksi
A1: RENCANA ANGGARAN BIAYA (RAB)
A2: Website Manajemen Kos (SIMA KOS) | V2: Sheetnya yang rinci
Q3: Biaya:
A4: A. INFRASTRUKTUR APLIKASI | Q4: 1. pengembangan | S4: (orang & AI)
A5: No | B5: Uraian | D5: Volume | H5: Harga | Q5: 2. operasional
D6: Jumlah | E6: Durasi | F6: Total | H6: Satuan | I6: Total | Q6: 3. materi/bahan: Server (cloud mana saja paketnya apa saja harus ada plan A,B,C,D diatur paket apa aja yang sesuai, database, API
A7: 1 | B7: Hosting & Domain (1 tahun) | D7: 1 | E7: 1 | F7: =D7*E7 -> 1 | H7: 4312000 | I7: =F7*H7 -> 4312000
A8: 2 | B8: Supabase Pro Plan (1 tahun, estimasi) | D8: 1 | E8: 1 | F8: =D8*E8 -> 1 | H8: 5390000 | I8: =F8*H8 -> 5390000
A9: 3 | B9: WhatsApp API pihak ketiga, mis. Fonnte (1 tahun, estimasi) | D9: 1 | E9: 1 | F9: =D9*E9 -> 1 | H9: 4260000 | I9: =F9*H9 -> 4260000 | Q9: biaya library: phyton dll
A10: Subtotal A. Infrastruktur Aplikasi | I10: =SUM(I7:I9) -> 13962000 | Q10: Infrastruktur harus ada referensinya, apakah Alibaba atau Azure dll
Q11: 1 pertanyaan 1 jawaban
A12: B. BIAYA PENGEMBANGAN PER FITUR & FUNGSI DASAR (Versi 1.0) | Q12: misal: Apakah pernah pakai sosial media? sosmed apa aja yang pernah dipakai? sosmed yg paling disukai? banyak pertanyaan tapi tujuannya sama.
A13: No | B13: Fitur | C13: Fungsi Dasar | D13: Jml Dev | E13: Durasi (Hari) | F13: Total OH | G13: Faktor Kesulitan | H13: Harga Dasar/OH | I13: Biaya Fungsi | J13: Versi | Q13: pitching : fiturnya apa tujuannya apa
A14: 1 | B14: Desain UI/UX Aplikasi | C14: Wireframe & Mockup | D14: 1 | E14: 3 | F14: =D14*E14 -> 3 | G14: 1 | H14: 30000 | I14: =F14*G14*H14 -> 90000 | J14: V1.0
A15: 2 | B15: Desain UI/UX Aplikasi | C15: Desain UI Final & Asset Grafis | D15: 1 | E15: 3 | F15: =D15*E15 -> 3 | G15: 1.3 | H15: 30000 | I15: =F15*G15*H15 -> 117000 | J15: V1.0 | Q15: metode tidak dibayar
A16: 3 | B16: Autentikasi & Verifikasi User | C16: Register & Login | D16: 2 | E16: 3 | F16: =D16*E16 -> 6 | G16: 1 | H16: 50000 | I16: =F16*G16*H16 -> 300000 | J16: V1.0 | Q16: yang dibayar adalah fungsi misalnya auth
A17: 4 | B17: Autentikasi & Verifikasi User | C17: Verifikasi Akun oleh Admin | D17: 2 | E17: 2 | F17: =D17*E17 -> 4 | G17: 1.3 | H17: 50000 | I17: =F17*G17*H17 -> 260000 | J17: V1.0 | Q17: BUAT YANG UMUM HABIS ITU YANG KERJ NGIKUTI YANG UMUM ITU TADI harganya mengikuti tingkat kesulitan
A18: 5 | B18: Melihat & Memilih Kamar | C18: Listing Kamar Tersedia | D18: 2 | E18: 2 | F18: =D18*E18 -> 4 | G18: 1 | H18: 50000 | I18: =F18*G18*H18 -> 200000 | J18: V1.0 | Q18: referensi cloudnya harus ada
A19: 6 | B19: Melihat & Memilih Kamar | C19: Detail Kamar (foto, harga, fasilitas) | D19: 2 | E19: 2 | F19: =D19*E19 -> 4 | G19: 1 | H19: 50000 | I19: =F19*G19*H19 -> 200000 | J19: V1.0 | Q19: Pertanyaan wawancara diambil dari fitur2 yang ditawarkan
A20: 7 | B20: Integrasi Chat WhatsApp Langsung | C20: Tombol Klik-to-Chat dari Web | D20: 1 | E20: 3 | F20: =D20*E20 -> 3 | G20: 1 | H20: 50000 | I20: =F20*G20*H20 -> 150000 | J20: V1.0 | Q20: ringkasan : isi
A21: 8 | B21: Booking Kamar | C21: Form & Validasi Ketersediaan | D21: 2 | E21: 4 | F21: =D21*E21 -> 8 | G21: 1.6 | H21: 50000 | I21: =F21*G21*H21 -> 640000 | J21: V1.0 | Q21: VERSI PERTAMA FITURNYA YANG GAMPANG BARU DIKASIH FITUR YANG LEBIH KOMPLEKS DI VERSI 2 NYA
A22: 9 | B22: Booking Kamar | C22: Konfirmasi & Notifikasi Booking | D22: 2 | E22: 3 | F22: =D22*E22 -> 6 | G22: 1.3 | H22: 50000 | I22: =F22*G22*H22 -> 390000 | J22: V1.0 | Q22: pengembangan
A23: 10 | B23: Pembatalan Booking | C23: Form Pengajuan Pembatalan | D23: 2 | E23: 2 | F23: =D23*E23 -> 4 | G23: 1 | H23: 50000 | I23: =F23*G23*H23 -> 200000 | J23: V1.0 | Q23: biaya
A24: 11 | B24: Pembatalan Booking | C24: Validasi Syarat Pembatalan | D24: 2 | E24: 1 | F24: =D24*E24 -> 2 | G24: 1.3 | H24: 50000 | I24: =F24*G24*H24 -> 130000 | J24: V1.0
A25: 12 | B25: Pengajuan Perpanjangan Booking | C25: Form Pengajuan Perpanjangan | D25: 2 | E25: 2 | F25: =D25*E25 -> 4 | G25: 1 | H25: 50000 | I25: =F25*G25*H25 -> 200000 | J25: V1.0
A26: 13 | B26: Pengajuan Perpanjangan Booking | C26: Validasi Syarat (H-7 s.d H-30, lunas tagihan) | D26: 2 | E26: 2 | F26: =D26*E26 -> 4 | G26: 1.3 | H26: 50000 | I26: =F26*G26*H26 -> 260000 | J26: V1.0
A27: 14 | B27: Riwayat Booking & Pembayaran (Profil User) | C27: Riwayat Booking | D27: 1 | E27: 2 | F27: =D27*E27 -> 2 | G27: 1 | H27: 50000 | I27: =F27*G27*H27 -> 100000 | J27: V1.0
A28: 15 | B28: Riwayat Booking & Pembayaran (Profil User) | C28: Riwayat Pembayaran | D28: 1 | E28: 2 | F28: =D28*E28 -> 2 | G28: 1 | H28: 50000 | I28: =F28*G28*H28 -> 100000 | J28: V1.0 | R28: 1jt per fitur dibagi lagi per fungsi (di rincikan lagi: auth -> database dll boleh dikarang di bagian fungsi)
A29: 16 | B29: Verifikasi Pembayaran (Admin) | C29: Upload & Cek Bukti Bayar | D29: 2 | E29: 2 | F29: =D29*E29 -> 4 | G29: 1 | H29: 50000 | I29: =F29*G29*H29 -> 200000 | J29: V1.0
A30: 17 | B30: Verifikasi Pembayaran (Admin) | C30: Approve / Reject Pembayaran | D30: 2 | E30: 2 | F30: =D30*E30 -> 4 | G30: 1.3 | H30: 50000 | I30: =F30*G30*H30 -> 260000 | J30: V1.0 | R30: disesuaikan dengan perusahaan tempat aplikasi akan dipasarkan
A31: 18 | B31: Kelola Data Kos & Kamar (Admin) | C31: CRUD Data Kos | D31: 2 | E31: 2 | F31: =D31*E31 -> 4 | G31: 1 | H31: 50000 | I31: =F31*G31*H31 -> 200000 | J31: V1.0
A32: 19 | B32: Kelola Data Kos & Kamar (Admin) | C32: CRUD Data Kamar | D32: 2 | E32: 3 | F32: =D32*E32 -> 6 | G32: 1 | H32: 50000 | I32: =F32*G32*H32 -> 300000 | J32: V1.0
A33: 20 | B33: Kelola Pengajuan User (Admin) | C33: Approve / Reject Pembatalan | D33: 2 | E33: 2 | F33: =D33*E33 -> 4 | G33: 1 | H33: 50000 | I33: =F33*G33*H33 -> 200000 | J33: V1.0
A34: 21 | B34: Kelola Pengajuan User (Admin) | C34: Approve / Reject Perpanjangan | D34: 2 | E34: 2 | F34: =D34*E34 -> 4 | G34: 1 | H34: 50000 | I34: =F34*G34*H34 -> 200000 | J34: V1.0
A35: 22 | B35: Dashboard & Laporan (Admin) | C35: Dashboard Ringkasan | D35: 1 | E35: 3 | F35: =D35*E35 -> 3 | G35: 1.3 | H35: 40000 | I35: =F35*G35*H35 -> 156000 | J35: V1.0 | S35: indikator, referensi, pertanyaan, target
A36: 23 | B36: Dashboard & Laporan (Admin) | C36: Laporan Histori Transaksi | D36: 1 | E36: 2 | F36: =D36*E36 -> 2 | G36: 1 | H36: 40000 | I36: =F36*G36*H36 -> 80000 | J36: V1.0
A37: 24 | B37: Testing & QA Keseluruhan Sistem | C37: Testing Fungsional Seluruh Sistem | D37: 1 | E37: 5 | F37: =D37*E37 -> 5 | G37: 1 | H37: 20000 | I37: =F37*G37*H37 -> 100000 | J37: V1.0 | R37: RAB, NOMINAL YG DITARGETKAN
A38: Subtotal B. Biaya Pengembangan (Versi 1.0 masuk Total Anggaran) | I38: =SUM(I14:I37) -> 5033000 | R38: FITUR YANG SULIT2 DI TAMPILKAN DI VERSI SELANJUTNYA, VERSI AWAL YANG MUDAH2
A40: Roadmap Pengembangan Lanjutan Versi 2.0 (Tidak masuk Total Anggaran saat ini)
A41: 25 | B41: Sistem Rekomendasi Kamar Otomatis (AHP+SAW) | C41: Implementasi Model AHP (pembobotan kriteria) | D41: 2 | E41: 5 | F41: =D41*E41 -> 10 | G41: 1.6 | H41: 50000 | I41: =F41*G41*H41 -> 800000 | J41: V2.0
...

Sheet Sumber Dana
A1: SUMBER DANA
A2: Rencana Pendanaan (SIMA KOS)
A4: No | B4: Sumber Dana | C4: Keterangan | D4: Jumlah (Rp) | E4: % dari Total | H4: Laporan akhir: SAD yg diimprovekan
A5: 1 | B5: Dana Pribadi / Patungan Anggota Tim | C5: Iuran internal tim pengembang | D5: ='RAB - Biaya Produksi'!I56 -> 21664500 | E5: =D5/'RAB - Biaya Produksi'!I56 -> 1 | H5: Tujuan proyek bisa diperkuat dengan daftar wawancara di sheet tadi
A6: 2 | B6: Dana Hibah / Kompetisi Kewirausahaan | C6: 0 | D6: 0 | E6: =D6/'RAB - Biaya Produksi'!I56 -> 0
A7: 3 | B7: Investor / Pinjaman Pihak Ketiga | C7: 0 | D7: 0 | E7: =D7/'RAB - Biaya Produksi'!I56 -> 0
A8: TOTAL SUMBER DANA | D8: =SUM(D5:D7) -> 21664500 | E8: =D8/'RAB - Biaya Produksi'!I56 -> 1

Sheet Skema Harga ke Klien
A1: SKEMA HARGA JUAL KE KLIEN (PEMILIK KOS)
A2: Dihitung dari Total Anggaran (Biaya Produksi) di sheet 'RAB - Biaya Produksi'
A4: Referensi: Biaya Produksi Total
A5: Total Biaya Produksi (A+B+C+Tak Terduga) | B5: ='RAB - Biaya Produksi'!I56 -> 21664500
A6: Biaya Pengembangan saja (Bagian B, V1.0) | B6: ='RAB - Biaya Produksi'!I38 -> 5033000
A7: Biaya Infrastruktur per Tahun (Bagian A) | B7: ='RAB - Biaya Produksi'!I10 -> 13962000
A9: Model Harga | B9: Deskripsi untuk Klien | C9: Cara Hitung | D9: Estimasi Harga
A10: Margin Sekali Bayar | B10: 0.3 | C10: (asumsi margin keuntungan, bisa diubah)
A11: Margin Serah Terima | B11: 0.5 | C11: (lebih tinggi karena melepas source code & hak kelola penuh)
A12: Margin Maintenance Bulanan | B12: 0.25 | C12: (markup di atas biaya infrastruktur bulanan, untuk skema langganan)
A14: Sekali Bayar (One-time Purchase) | B14: Klien bayar satu kali untuk hak pakai sistem di 1 properti kos. Support & maintenance terbatas (mis. 3 bulan gratis, selanjutnya opsional). | C14: Total Biaya Produksi x (1 + Margin Sekali Bayar) | D14: =B5*(1+B10) -> 28163850
A15: Berlangganan (Subscription) | B15: Klien bayar biaya setup awal lebih ringan, lalu biaya langganan bulanan yang sudah mencakup hosting, database, API WA, dan maintenance. | C15: Setup: 50% Biaya Pengembangan. Bulanan: (Biaya Infra Tahunan ÷ 12) x (1 + Margin Maintenance) | D15: ="Setup: Rp"&TEXT(B6*0.5,"#,##0")&" | Bulanan: Rp"&TEXT((B7/12)*(1+B12),"#,##0") -> Setup: Rp2516500,0 | Bulanan: Rp1454375,0
A16: Serah Terima (Full Handover) | B16: Source code & hak kelola penuh diserahkan ke klien (termasuk training/transfer knowledge). Klien mengurus infrastruktur & maintenance sendiri setelahnya. | C16: Total Biaya Produksi x (1 + Margin Serah Terima) | D16: =B5*(1+B11) -> 32496750
